Getting error while importing GeoPandas in Python console I have installed GeoPandas and its dependencies using pip install package_name. Here is the pip list output:Package         Version     attrs           18.2.0<br>Click           7.0<br>click-plugins   1.0.4<br>cligj           0.5.0<br>cycler          0.10.0<br>descartes       1.1.0<br>Fiona           1.8.4<br>geographiclib   1.49<br>geopandas       0.4.0<br>geopy           1.18.1<br>kiwisolver      1.0.1<br>matplotlib      2.2.3<br>munch           2.3.2<br>numpy           1.15.4<br>pandas          0.22.0<br>pip             18.1<br>psycopg2        2.7.6.1<br>pyparsing       2.3.0<br>pyproj          1.9.5.1<br>PySAL           1.14.4.post2python-dateutil 2.7.5<br>pytz            2018.7<br>Rtree           0.8.3<br>scipy           1.2.0<br>setuptools      40.6.3<br>Shapely         1.6.4.post2 six             1.12.0<br>wheel           0.32.3But as soon as i am importing it in Python console as <blockquote>  import geopandas</blockquote>I am getting an error as <blockquote>  Traceback (most recent call last):   File \"\line 1, in     File  \"/home/rajesh/panda_projects/env/lib/python3.4/site-packages/geopandas/init.py\ line 1, in       from geopandas.geoseries import GeoSeries   File \"/home/rajesh/panda_projects/env/lib/python3.4/site-packages/geopandas/geoseries.py\ line 5, in       from pandas import Series   File \"/home/rajesh/panda_projects/env/lib/python3.4/site-packages/pandas/init.py\ line 26, in       from pandas._libs import (hashtable as _hashtable,   File \"/home/rajesh/panda_projects/env/lib/python3.4/site-packages/pandas/_libs/init.py\ line 4, in       from .tslib import iNaT, NaT, Timestamp, Timedelta, OutOfBoundsDatetime   File \"pandas/_libs/src/numpy.pxd\line 865, in  init pandas._libs.tslib ValueError: numpy.ufunc has the wrong size,  try recompiling. Expected 192, got 216</blockquote>What is the solution for this?